modules loaded
beginning preprocessing
bids-validator@1.4.0

	[31m1: [ERR] A json sidecar file was found without a corresponding data file (code: 90 - SIDECAR_WITHOUT_DATAFILE)[39m
		./sub-f10112/ses-1/fmap/sub-f10112_ses-1_magnitude1.json
		./sub-f10112/ses-1/fmap/sub-f10112_ses-1_phase1.json
		./sub-f10112/ses-1/fmap/sub-f10112_ses-1_phase2.json

[36m	Please visit https://neurostars.org/search?q=SIDECAR_WITHOUT_DATAFILE for existing conversations about this issue.[39m

	[33m1: [WARN] The recommended file /README is missing. See Section 03 (Modality agnostic files) of the BIDS specification. (code: 101 - README_FILE_MISSING)[39m

[36m	Please visit https://neurostars.org/search?q=README_FILE_MISSING for existing conversations about this issue.[39m


        [34m[4mSummary:[24m[39m                   [34m[4mAvailable Tasks:[24m[39m        [34m[4mAvailable Modalities:[24m[39m 
        2383 Files, 68.84GB        mid                     T1w                   
        111 - Subjects             rest                    bold                  
        1 - Session                                        events                
                                                           fieldmap              


[36m	If you have any questions, please post on https://neurostars.org/tags/bids.[39m

You are using fMRIPrep-20.2.3, and a newer version of fMRIPrep is available: 22.0.2.
Please check out our documentation about how and when to upgrade:
https://fmriprep.readthedocs.io/en/latest/faq.html#upgrading
Traceback (most recent call last):
  File "/usr/local/miniconda/bin/fmriprep", line 10, in <module>
    sys.exit(main())
  File "/usr/local/miniconda/lib/python3.7/site-packages/fmriprep/cli/run.py", line 17, in main
    parse_args()
  File "/usr/local/miniconda/lib/python3.7/site-packages/fmriprep/cli/parser.py", line 724, in parse_args
    config.environment.exec_env, opts.bids_dir, opts.participant_label
  File "/usr/local/miniconda/lib/python3.7/site-packages/fmriprep/utils/bids.py", line 155, in validate_input_dir
    subprocess.check_call(['bids-validator', bids_dir, '-c', temp.name])
  File "/usr/local/miniconda/lib/python3.7/subprocess.py", line 341, in check_call
    raise CalledProcessError(retcode, cmd)
subprocess.CalledProcessError: Command '['bids-validator', PosixPath('/projects/b1108/studies/foundations/data/raw/neuroimaging/bids'), '-c', '/tmp/tmp6fexqd5e']' returned non-zero exit status 1.
